[2025-04-07T01:56:13.258+0000] {taskinstance.py:1956} INFO - Dependencies all met for dep_context=non-requeueable deps ti=<TaskInstance: anac_pipeline_dag.baixar_csv_anac manual__2025-04-07T01:37:52.587480+00:00 [queued]>
[2025-04-07T01:56:13.265+0000] {taskinstance.py:1956} INFO - Dependencies all met for dep_context=requeueable deps ti=<TaskInstance: anac_pipeline_dag.baixar_csv_anac manual__2025-04-07T01:37:52.587480+00:00 [queued]>
[2025-04-07T01:56:13.266+0000] {taskinstance.py:2170} INFO - Starting attempt 4 of 4
[2025-04-07T01:56:13.277+0000] {taskinstance.py:2191} INFO - Executing <Task(PythonOperator): baixar_csv_anac> on 2025-04-07 01:37:52.587480+00:00
[2025-04-07T01:56:13.281+0000] {standard_task_runner.py:60} INFO - Started process 503 to run task
[2025-04-07T01:56:13.284+0000] {standard_task_runner.py:87} INFO - Running: ['***', 'tasks', 'run', 'anac_pipeline_dag', 'baixar_csv_anac', 'manual__2025-04-07T01:37:52.587480+00:00', '--job-id', '7', '--raw', '--subdir', 'DAGS_FOLDER/dag_anac_pipeline.py', '--cfg-path', '/tmp/tmpv2n_vdef']
[2025-04-07T01:56:13.286+0000] {standard_task_runner.py:88} INFO - Job 7: Subtask baixar_csv_anac
[2025-04-07T01:56:13.301+0000] {logging_mixin.py:188} WARNING - /home/***/.local/lib/python3.10/site-packages/***/settings.py:194 DeprecationWarning: The sql_alchemy_conn option in [core] has been moved to the sql_alchemy_conn option in [database] - the old setting has been used, but please update your config.
[2025-04-07T01:56:13.336+0000] {task_command.py:423} INFO - Running <TaskInstance: anac_pipeline_dag.baixar_csv_anac manual__2025-04-07T01:37:52.587480+00:00 [running]> on host 8a43643a16f6
[2025-04-07T01:56:13.408+0000] {taskinstance.py:2480} INFO - Exporting env vars: AIRFLOW_CTX_DAG_OWNER='***' AIRFLOW_CTX_DAG_ID='anac_pipeline_dag' AIRFLOW_CTX_TASK_ID='baixar_csv_anac' AIRFLOW_CTX_EXECUTION_DATE='2025-04-07T01:37:52.587480+00:00' AIRFLOW_CTX_TRY_NUMBER='4' AIRFLOW_CTX_DAG_RUN_ID='manual__2025-04-07T01:37:52.587480+00:00'
[2025-04-07T01:56:16.073+0000] {logging_mixin.py:188} INFO - [INFO] Baixando arquivo de: https://sistemas.anac.gov.br/dadosabertos/Voos%20e%20operações%20aéreas/Dados%20Estatísticos%20do%20Transporte%20Aéreo/Dados_Estatisticos.csv
[2025-04-07T01:56:16.074+0000] {logging_mixin.py:188} INFO - [DEBUG] Salvando em: /opt/***/data/bronze/Dados_Estatisticos.csv
[2025-04-07T01:57:47.873+0000] {taskinstance.py:2698} ERROR - Task failed with exception
Traceback (most recent call last):
  File "/home/airflow/.local/lib/python3.10/site-packages/urllib3/response.py", line 710, in _error_catcher
    yield
  File "/home/airflow/.local/lib/python3.10/site-packages/urllib3/response.py", line 835, in _raw_read
    raise IncompleteRead(self._fp_bytes_read, self.length_remaining)
urllib3.exceptions.IncompleteRead: IncompleteRead(30850815 bytes read, 309703048 more expected)

The above exception was the direct cause of the following exception:

Traceback (most recent call last):
  File "/home/airflow/.local/lib/python3.10/site-packages/requests/models.py", line 816, in generate
    yield from self.raw.stream(chunk_size, decode_content=True)
  File "/home/airflow/.local/lib/python3.10/site-packages/urllib3/response.py", line 936, in stream
    data = self.read(amt=amt, decode_content=decode_content)
  File "/home/airflow/.local/lib/python3.10/site-packages/urllib3/response.py", line 907, in read
    data = self._raw_read(amt)
  File "/home/airflow/.local/lib/python3.10/site-packages/urllib3/response.py", line 813, in _raw_read
    with self._error_catcher():
  File "/usr/local/lib/python3.10/contextlib.py", line 153, in __exit__
    self.gen.throw(typ, value, traceback)
  File "/home/airflow/.local/lib/python3.10/site-packages/urllib3/response.py", line 727, in _error_catcher
    raise ProtocolError(f"Connection broken: {e!r}", e) from e
urllib3.exceptions.ProtocolError: ('Connection broken: IncompleteRead(30850815 bytes read, 309703048 more expected)', IncompleteRead(30850815 bytes read, 309703048 more expected))

During handling of the above exception, another exception occurred:

Traceback (most recent call last):
  File "/home/airflow/.local/lib/python3.10/site-packages/airflow/models/taskinstance.py", line 433, in _execute_task
    result = execute_callable(context=context, **execute_callable_kwargs)
  File "/home/airflow/.local/lib/python3.10/site-packages/airflow/operators/python.py", line 199, in execute
    return_value = self.execute_callable()
  File "/home/airflow/.local/lib/python3.10/site-packages/airflow/operators/python.py", line 216, in execute_callable
    return self.python_callable(*self.op_args, **self.op_kwargs)
  File "/opt/airflow/dags/tasks/download_csv.py", line 34, in baixar_csv_anac
    for chunk in csv_response.iter_content(chunk_size=1048576):  # 1MB
  File "/home/airflow/.local/lib/python3.10/site-packages/requests/models.py", line 818, in generate
    raise ChunkedEncodingError(e)
requests.exceptions.ChunkedEncodingError: ('Connection broken: IncompleteRead(30850815 bytes read, 309703048 more expected)', IncompleteRead(30850815 bytes read, 309703048 more expected))
[2025-04-07T01:57:47.887+0000] {taskinstance.py:1138} INFO - Marking task as FAILED. dag_id=anac_pipeline_dag, task_id=baixar_csv_anac, execution_date=20250407T013752, start_date=20250407T015613, end_date=20250407T015747
[2025-04-07T01:57:47.897+0000] {standard_task_runner.py:107} ERROR - Failed to execute job 7 for task baixar_csv_anac (('Connection broken: IncompleteRead(30850815 bytes read, 309703048 more expected)', IncompleteRead(30850815 bytes read, 309703048 more expected)); 503)
[2025-04-07T01:57:47.908+0000] {local_task_job_runner.py:234} INFO - Task exited with return code 1
[2025-04-07T01:57:47.922+0000] {taskinstance.py:3280} INFO - 0 downstream tasks scheduled from follow-on schedule check
